<?xml version="1.0"?>
<robot
  name="neuronbot2_description">

  <link name="base_footprint" />

  <link
    name="base_link">
    <inertial>
      <origin
        xyz="0 0 0"
        rpy="0 0 0" />
      <mass
        value="5" />
      <inertia
        ixx="0.09617045"
        ixy="3.5340082E-05"
        ixz="2.5462637E-04"
        iyy="0.1155512"
        iyz="-4.2933341E-05"
        izz="1.0718441E-01" />
    </inertial>
    <visual>
      <origin
        xyz="0 0 0"
        rpy="0 0 0" />
      <geometry>
        <mesh
          filename="package://neuronbot2_description/meshes/neuronbot2/base_link.stl" />
      </geometry>
    </visual>
    <collision>
      <origin
        xyz="0 0 0"
        rpy="0 0 0" />
      <geometry>
          <box size="0.33 0.33 0.2" />
      </geometry>
    </collision>
  </link>

  <link
    name="laser_frame">
    <inertial>
      <origin
        xyz="0 0 0"
        rpy="0 0 0" />
      <mass
        value="0.2" />
      <inertia
        ixx="8.4514E-05"
        ixy="7.288E-12"
        ixz="3.6379E-06"
        iyy="7.9969E-05"
        iyz="-3.7962E-10"
        izz="0.00011888" />
    </inertial>
    <visual>
      <origin
        xyz="0 0 0"
        rpy="0 0 0" />
      <geometry>
        <mesh
          filename="package://neuronbot2_description/meshes/neuronbot2/laser_link.stl" />
      </geometry>
    </visual>
    <collision>
      <origin
        xyz="0 0 0"
        rpy="0 0 0" />
      <geometry>
        <mesh
          filename="package://neuronbot2_description/meshes/neuronbot2/laser_link.stl" />
      </geometry>
    </collision>
  </link>

  <link name="imu_link"/>

  <link name="wheel_right_link">
    <visual>
      <origin xyz="0 0 0" rpy="0 0 0"/>
      <geometry>
        <cylinder length="0.025" radius="0.075"/>
      </geometry>
    </visual>
    <collision>
      <origin xyz="0 0 0" rpy="0 0 0"/>
      <geometry>
        <cylinder length="0.025" radius="0.075"/>
      </geometry>
    </collision>
    <inertial>
      <origin xyz="0 0 0" />
      <mass value="2.8498940e-02" />
      <inertia ixx="1.1175580e-05" ixy="-4.2369783e-11" ixz="-5.9381719e-09"
               iyy="1.1192413e-05" iyz="-1.4400107e-11"
               izz="2.0712558e-05" />
    </inertial>
  </link>

  <link name="wheel_left_link">
    <visual>
      <origin xyz="0 0 0" rpy="0 0 0"/>
      <geometry>
        <cylinder length="0.025" radius="0.075"/>
      </geometry>
    </visual>
    <collision>
      <origin xyz="0 0 0" rpy="0 0 0"/>
      <geometry>
        <cylinder length="0.025" radius="0.075"/>
      </geometry>
    </collision>
    <inertial>
      <origin xyz="0 0 0" />
      <mass value="2.8498940e-02" />
      <inertia ixx="1.1175580e-05" ixy="-4.2369783e-11" ixz="-5.9381719e-09"
               iyy="1.1192413e-05" iyz="-1.4400107e-11"
               izz="2.0712558e-05" />
    </inertial>
  </link>
  
  
  <joint name="base_link_joint" type="fixed">
    <parent link="base_footprint"/>
    <child link="base_link"/>
    <origin xyz="0 0 0" rpy="0 0 0"/>
  </joint>


  <joint
    name="laser_frame_joint"
    type="fixed">
    <origin
      xyz="0.125 0 0.33"
      rpy="0 0 3.14" />
    <parent link="base_link" />
    <child link="laser_frame" />
    <axis xyz="0 0 0" />
  </joint>

  <joint name="imu_joint" type="fixed">
    <parent link="base_link"/>
    <child link="imu_link"/>
    <origin rpy="0 0 0" xyz="0 0 0.11"/>
    <axis xyz="0 0 0" />
  </joint>
  
  <joint name="r_wheel_joint" type="continuous">
    <parent link="base_link"/>
    <child link="wheel_right_link"/>
    <origin xyz="0.0 -0.14 0.0745" rpy="1.57 0 0"/>
    <axis xyz="0 0 1"/>
  </joint>

  <joint name="l_wheel_joint" type="continuous">
    <parent link="base_link"/>
    <child link="wheel_left_link"/>
    <origin xyz="0.0 0.14 0.0745" rpy="1.57 0 0"/>
    <axis xyz="0 0 1"/>
  </joint>

</robot>